I'm sorry, but an uncaught exception occurred.

While running game code:
  File "game/nerkk_cap4.rpy", line 281, in script
    nerkk "Temos que voltar logo para deter [pronome] [causa]"
NameError: name 'causa' is not defined

-- Full Traceback ------------------------------------------------------------

Full traceback:
  File "game/nerkk_cap4.rpy", line 281, in script
    nerkk "Temos que voltar logo para deter [pronome] [causa]"
  File "C:\Users\Usuario\Documents\renpy\renpy-8.3.7-sdk\renpy\ast.py", line 2586, in execute
    Say.execute(self)
  File "C:\Users\Usuario\Documents\renpy\renpy-8.3.7-sdk\renpy\ast.py", line 623, in execute
    renpy.exports.say(who, what, *args, **kwargs)
  File "C:\Users\Usuario\Documents\renpy\renpy-8.3.7-sdk\renpy\exports\sayexports.py", line 132, in say
    who(what, *args, **kwargs)
  File "C:\Users\Usuario\Documents\renpy\renpy-8.3.7-sdk\renpy\character.py", line 1456, in __call__
    what = self.prefix_suffix("what", self.what_prefix, what, self.what_suffix)
  File "C:\Users\Usuario\Documents\renpy\renpy-8.3.7-sdk\renpy\character.py", line 1369, in prefix_suffix
    return (sub(prefix) + sub(body) + sub(suffix))
  File "C:\Users\Usuario\Documents\renpy\renpy-8.3.7-sdk\renpy\character.py", line 1349, in sub
    return renpy.substitutions.substitute(s, scope=scope, force=force, translate=translate)[0]
  File "C:\Users\Usuario\Documents\renpy\renpy-8.3.7-sdk\renpy\substitutions.py", line 373, in substitute
    s = interpolate(s, variables) # type: ignore
  File "C:\Users\Usuario\Documents\renpy\renpy-8.3.7-sdk\renpy\substitutions.py", line 86, in interpolate
    raise e
  File "C:\Users\Usuario\Documents\renpy\renpy-8.3.7-sdk\renpy\substitutions.py", line 78, in interpolate
    value = renpy.python.py_eval(code, {}, scope)
  File "C:\Users\Usuario\Documents\renpy\renpy-8.3.7-sdk\renpy\python.py", line 1218, in py_eval
    return py_eval_bytecode(code, globals, locals)
  File "C:\Users\Usuario\Documents\renpy\renpy-8.3.7-sdk\renpy\python.py", line 1211, in py_eval_bytecode
    return eval(bytecode, globals, locals)
  File "<none>", line 1, in <module>
NameError: name 'causa' is not defined

Windows-10-10.0.22621 AMD64
Ren'Py 8.3.7.25031702
Kaua 1.0
Sun May 18 11:17:33 2025
