I'm sorry, but an uncaught exception occurred.

While running game code:
  File "game/nerkk_cap3.rpy", line 232, in script
    show nerkk ataque at right
Exception: Image 'nerkk' does not accept attributes 'ataque'.

-- Full Traceback ------------------------------------------------------------

Full traceback:
  File "game/nerkk_cap3.rpy", line 232, in script
    show nerkk ataque at right
  File "/home/enzo/Downloads/renpy-8.3.7-sdk/renpy/ast.py", line 1124, in execute
    show_imspec(self.imspec, atl=getattr(self, "atl", None))
  File "/home/enzo/Downloads/renpy-8.3.7-sdk/renpy/ast.py", line 1087, in show_imspec
    renpy.config.show(name,
  File "/home/enzo/Downloads/renpy-8.3.7-sdk/renpy/exports/displayexports.py", line 477, in show
    if not base.find_target() and renpy.config.missing_show:
  File "/home/enzo/Downloads/renpy-8.3.7-sdk/renpy/display/image.py", line 421, in find_target
    self.target = target._duplicate(a)
  File "/home/enzo/Downloads/renpy-8.3.7-sdk/renpy/display/transform.py", line 1188, in _duplicate
    args.extraneous()
  File "/home/enzo/Downloads/renpy-8.3.7-sdk/renpy/display/displayable.py", line 109, in extraneous
    raise Exception("Image '{}' does not accept attributes '{}'.".format(
Exception: Image 'nerkk' does not accept attributes 'ataque'.

Linux-6.12.10-76061203-generic-x86_64-with-glibc2.35 x86_64
Ren'Py 8.3.7.25031702
Kaua 1.0
Fri May 16 16:06:48 2025
